Workbook

Sheet EXTRUSION
A1: Extrusion Costing
A3: XLMP-0.9 Ladder
A4: Details | M4: Costing | N4: Costing | O4: Costing
A5: Info | B5: EA Stock Number | C5: Description | D5: Add Work | E5: Status | F5: Section No | G5: Size | H5: Linear Weight | I5: Cut Length | J5: Item Qty | K5: Total Weight | M5: Naked Cost/ pc (RM) | N5: Naked Cost/ pc (RM) | O5: Naked Cost/ pc (RM)
A7: L04 | B7: UA1711 | C7: 60x60x6 Angle | D7: Drill as shown. Trim as shown. | E7: Existing Profile | F7: EA 6097 | G7: 60.00mm x 60.00mm x 6.00mm | H7: 1.854 | I7: 672 | J7: 2 | K7: =SUM(H7*(I7/1000)*J7) -> 2.491776 | M7: =SUM(H7*(I7/1000)*J7*25) -> 62.2944 | N7: =SUM(H7*(I7/1000)*J7*22) -> 54.819072 | O7: =SUM(H7*(I7/1000)*J7*22) -> 54.819072
A8: L03 | B8: UA1123 | C8: 50x50x6 Angle | D8: Drill as shown | E8: Similar Profile | F8: EA 6092 | G8: 50.80mm x 50.80mm x 6.00mm | H8: 1.554 | I8: 160 | J8: 4 | K8: =SUM(H8*(I8/1000)*J8) -> 0.99456 | M8: =SUM(H8*(I8/1000)*J8*25) -> 24.864 | N8: =SUM(H8*(I8/1000)*J8*22) -> 21.88032 | O8: =SUM(H8*(I8/1000)*J8*22) -> 21.88032
A9: L05 | B9: UA3178 | C9: 50x50x3 RHS | E9: Similar Profile | F9: SH 4029 | G9: 50.80mm x 50.80mm x 3.00mm | H9: 1.554 | I9: 168 | J9: 4 | K9: =SUM(H9*(I9/1000)*J9) -> 1.044288 | M9: =SUM(H9*(I9/1000)*J9*25) -> 26.1072 | N9: =SUM(H9*(I9/1000)*J9*22) -> 22.974336 | O9: =SUM(H9*(I9/1000)*J9*22) -> 22.974336
A10: L01 | B10: 614511 | C10: 50x50x3 T-Slot RHS | E10: New Profile | F10: C2464 | H10: 2.178 | I10: 2260 | J10: 2 | K10: =SUM(H10*(I10/1000)*J10) -> 9.84456 | M10: =SUM(H10*(I10/1000)*J10*25) -> 246.114 | N10: =SUM(H10*(I10/1000)*J10*22) -> 216.58032 | O10: =SUM(H10*(I10/1000)*J10*22) -> 216.58032
A11: L02 | B11: 65556598 | C11: DSL Rung 38x32x2 | E11: New Profile | F11: C2465 | H11: 0.722 | I11: 550 | J11: 3 | K11: =SUM(H11*(I11/1000)*J11) -> 1.1913 | M11: =SUM(H11*(I11/1000)*J11*25) -> 29.7825 | N11: =SUM(H11*(I11/1000)*J11*22) -> 26.2086 | O11: =SUM(H11*(I11/1000)*J11*22) -> 26.2086
I12: Sub total weight | K12: =SUM(K7:K11) -> 15.566484 | M12: =SUM(M7:M11) -> 389.1621 | N12: =SUM(N7:N11) -> 342.46265 | O12: =SUM(O7:O11) -> 342.46265
I13: Price/kg | M13: =M12/K12 -> 25 | N13: =N12/K12 -> 22 | O13: =O12/K12 -> 22
I14: Total for NAR | K14: =K12 -> 15.566484 | M14: =M12 -> 389.1621 | N14: =N12 -> 342.46265 | O14: =O12 -> 342.46265
I15: Total weight + 3% for EA | K15: =K14/0.97 -> 16.047922
I16: To quote EA based on total weight + 3% (10%) (RM) | M16: =(K15*M13)/0.9 -> 445.7756 | N16: =(K15*N13)/0.9 -> 392.28253 | O16: =(K15*O13)/0.9 -> 392.28253
I17: To quote EA (10%) (USD) | M17: =M16/3.8 -> 117.30937 | N17: =N16/3.8 -> 103.23224 | O17: =O16/3.9 -> 100.58526
A21: XLMP-1.2 Ladder
A22: Details | M22: Costing | N22: Costing | O22: Costing
A23: Info | B23: EA Stock Number | C23: Description | D23: Add Work | E23: Status | F23: Section No | G23: Size | H23: Linear Weight | I23: Cut Length | J23: Item Qty | K23: Total Weight | M23: Naked Cost/ pc (RM) | N23: Naked Cost/ pc (RM) | O23: Naked Cost/ pc (RM)
A25: L04 | B25: UA1711 | C25: 60x60x6 Angle | D25: Drill as shown. Trim as shown. | E25: Existing Profile | F25: EA 6097 | G25: 60.00mm x 60.00mm x 6.00mm | H25: 1.854 | I25: 672 | J25: 2 | K25: =SUM(H25*(I25/1000)*J25) -> 2.491776 | M25: =SUM(H25*(I25/1000)*J25*25) -> 62.2944 | N25: =SUM(H25*(I25/1000)*J25*22) -> 54.819072 | O25: =SUM(H25*(I25/1000)*J25*22) -> 54.819072
A26: L03 | B26: UA1123 | C26: 50x50x6 Angle | D26: Drill as shown | E26: Similar Profile | F26: EA 6092 | G26: 50.80mm x 50.80mm x 6.00mm | H26: 1.554 | I26: 160 | J26: 4 | K26: =SUM(H26*(I26/1000)*J26) -> 0.99456 | M26: =SUM(H26*(I26/1000)*J26*25) -> 24.864 | N26: =SUM(H26*(I26/1000)*J26*22) -> 21.88032 | O26: =SUM(H26*(I26/1000)*J26*22) -> 21.88032
A27: L05 | B27: UA3178 | C27: 50x50x3 RHS | E27: Similar Profile | F27: SH 4029 | G27: 50.80mm x 50.80mm x 3.00mm | H27: 1.554 | I27: 168 | J27: 4 | K27: =SUM(H27*(I27/1000)*J27) -> 1.044288 | M27: =SUM(H27*(I27/1000)*J27*25) -> 26.1072 | N27: =SUM(H27*(I27/1000)*J27*22) -> 22.974336 | O27: =SUM(H27*(I27/1000)*J27*22) -> 22.974336
A28: L01 | B28: 614511 | C28: 50x50x3 T-Slot RHS | E28: New Profile | F28: C2464 | H28: 2.178 | I28: 2560 | J28: 2 | K28: =SUM(H28*(I28/1000)*J28) -> 11.15136 | M28: =SUM(H28*(I28/1000)*J28*25) -> 278.784 | N28: =SUM(H28*(I28/1000)*J28*22) -> 245.32992 | O28: =SUM(H28*(I28/1000)*J28*22) -> 245.32992
A29: L02 | B29: 65556598 | C29: DSL Rung 38x32x2 | E29: New Profile | F29: C2465 | H29: 0.722 | I29: 550 | J29: 4 | K29: =SUM(H29*(I29/1000)*J29) -> 1.5884 | M29: =SUM(H29*(I29/1000)*J29*25) -> 39.71 | N29: =SUM(H29*(I29/1000)*J29*22) -> 34.9448 | O29: =SUM(H29*(I29/1000)*J29*22) -> 34.9448
I30: Sub total weight | K30: =SUM(K25:K29) -> 17.270384 | M30: =SUM(M25:M29) -> 431.7596 | N30: =SUM(N25:N29) -> 379.94845 | O30: =SUM(O25:O29) -> 379.94845
I31: Price/kg | M31: =M30/K30 -> 25 | N31: =N30/K30 -> 22 | O31: =O30/K30 -> 22
I32: Total for NAR | K32: =K30 -> 17.270384 | M32: =M30 -> 431.7596 | N32: =N30 -> 379.94845 | O32: =O30 -> 379.94845
I33: Total weight + 3% for EA | K33: =K32/0.97 -> 17.80452
I34: To quote EA based on total weight + 3% (10%) (RM) | M34: =(K33*M31)/0.9 -> 494.56999 | N34: =(K33*N31)/0.9 -> 435.22159 | O34: =(K33*O31)/0.9 -> 435.22159
I35: To quote EA (10%) (USD) | M35: =M34/3.8 -> 130.15 | N35: =N34/3.8 -> 114.532 | O35: =O34/3.9 -> 111.59528
A38: XLMP-1.5 Ladder
A39: Details | M39: Costing | N39: Costing | O39: Costing
A40: Info | B40: EA Stock Number | C40: Description | D40: Add Work | E40: Status | F40: Section No | G40: Size | H40: Linear Weight | I40: Cut Length | J40: Item Qty | K40: Total Weight | M40: Naked Cost/ pc (RM) | N40: Naked Cost/ pc (RM) | O40: Naked Cost/ pc (RM)
A42: L04 | B42: UA1711 | C42: 60x60x6 Angle | D42: Drill as shown. Trim as shown. | E42: Existing Profile | F42: EA 6097 | G42: 60.00mm x 60.00mm x 6.00mm | H42: 1.854 | I42: 672 | J42: 2 | K42: =SUM(H42*(I42/1000)*J42) -> 2.491776 | M42: =SUM(H42*(I42/1000)*J42*25) -> 62.2944 | N42: =SUM(H42*(I42/1000)*J42*22) -> 54.819072 | O42: =SUM(H42*(I42/1000)*J42*22) -> 54.819072
A43: L03 | B43: UA1123 | C43: 50x50x6 Angle | D43: Drill as shown | E43: Similar Profile | F43: EA 6092 | G43: 50.80mm x 50.80mm x 6.00mm | H43: 1.554 | I43: 160 | J43: 4 | K43: =SUM(H43*(I43/1000)*J43) -> 0.99456 | M43: =SUM(H43*(I43/1000)*J43*25) -> 24.864 | N43: =SUM(H43*(I43/1000)*J43*22) -> 21.88032 | O43: =SUM(H43*(I43/1000)*J43*22) -> 21.88032
A44: L05 | B44: UA3178 | C44: 50x50x3 RHS | E44: Similar Profile | F44: SH 4029 | G44: 50.80mm x 50.80mm x 3.00mm | H44: 1.554 | I44: 168 | J44: 4 | K44: =SUM(H44*(I44/1000)*J44) -> 1.044288 | M44: =SUM(H44*(I44/1000)*J44*25) -> 26.1072 | N44: =SUM(H44*(I44/1000)*J44*22) -> 22.974336 | O44: =SUM(H44*(I44/1000)*J44*22) -> 22.974336
A45: L01 | B45: 614511 | C45: 50x50x3 T-Slot RHS | E45: New Profile | F45: C2464 | H45: 2.178 | I45: 2860 | J45: 2 | K45: =SUM(H45*(I45/1000)*J45) -> 12.45816 | M45: =SUM(H45*(I45/1000)*J45*25) -> 311.454 | N45: =SUM(H45*(I45/1000)*J45*22) -> 274.07952 | O45: =SUM(H45*(I45/1000)*J45*22) -> 274.07952
A46: L02 | B46: 65556598 | C46: DSL Rung 38x32x2 | E46: New Profile | F46: C2465 | H46: 0.722 | I46: 550 | J46: 5 | K46: =SUM(H46*(I46/1000)*J46) -> 1.9855 | M46: =SUM(H46*(I46/1000)*J46*25) -> 49.6375 | N46: =SUM(H46*(I46/1000)*J46*22) -> 43.681 | O46: =SUM(H46*(I46/1000)*J46*22) -> 43.681
I47: Sub total weight | K47: =SUM(K42:K46) -> 18.974284 | M47: =SUM(M42:M46) -> 474.3571 | N47: =SUM(N42:N46) -> 417.43425 | O47: =SUM(O42:O46) -> 417.43425
I48: Price/kg | M48: =M47/K47 -> 25 | N48: =N47/K47 -> 22 | O48: =O47/K47 -> 22
I49: Total for NAR | K49: =K47 -> 18.974284 | M49: =M47 -> 474.3571 | N49: =N47 -> 417.43425 | O49: =O47 -> 417.43425
...

Sheet ACCESSORIES & OTHER PARTS
A1: Accessories & Other Parts Costings
A3: PARTS BY NAR 7:3 Profit Sharing (3 & 4 STEPS)
A4: Photo | B4: Parts | C4: Naked Cost (RM) | D4: Qty | E4: EA Target Cost (USD) | F4: Price to Quote EA (USD) | G4: Price to Quote EA (RM) | H4: Profit | I4: NAR | K4: LADDERTECH | L4: Remarks
I5: 70% Profit Sharing (RM) | J5: Cost to Insert In PO/pc (RM) | K5: 30% Profit Sharing (RM)
A6: 1) Other Materials
B7: Griptread Nosing50mm | C7: 25 | D7: 1 | G7: =C7*1.1 -> 27.5 | H7: =G7-C7 -> 2.5 | I7: =H7*0.7 -> 1.75 | J7: =C7+I7 -> 26.75 | K7: =H7*0.3 -> 0.75
A8: 2) CNC & Welding (Based on Laser)
B9: Overall ladder | C9: 100 | D9: 1 | G9: =C9*1.1 -> 110 | H9: =G9-C9 -> 10 | I9: =H9*0.7 -> 7 | J9: =C9+I9 -> 107 | K9: =H9*0.3 -> 3
B10: Steps | C10: 30 | D10: 1 | G10: =C10*1.1 -> 33 | H10: =G10-C10 -> 3 | I10: =H10*0.7 -> 2.1 | J10: =C10+I10 -> 32.1 | K10: =H10*0.3 -> 0.9
A11: 3) Packaging Material by NAR
B12: Cardboard & Strecth Film | C12: 5 | D12: 1 | G12: =C12*1.1 -> 5.5 | H12: =G12-C12 -> 0.5 | I12: =H12*0.7 -> 0.35 | J12: =C12+I12 -> 5.35 | K12: =H12*0.3 -> 0.15
A13: 4) Bolt & Nut
B14: M10x20T | C14: 0.4 | D14: 1 | E14: 0.31 | F14: 0.3 | G14: =F14*4.3 -> 1.29 | H14: =G14-C14 -> 0.89 | I14: 0.3 | J14: 0.3 | K14: 0.59 | L14: Laddertech open mould and direct give RM0.30 to NAR
B15: M10NUT | C15: 0.14 | D15: 1 | F15: 0.25 | G15: =F15*4.3 -> 1.075 | H15: =G15-C15 -> 0.935 | I15: =H15*0.7 -> 0.6545 | J15: =C15+I15 -> 0.7945 | K15: =H15*0.3 -> 0.2805 | L15: Own markup for Price quoted to EA. No %
B16: Rivet | C16: 1 | D16: 1 | G16: =C16/0.9 -> 1.1111111 | H16: =G16-C16 -> 0.11111111 | I16: =H16*0.5 -> 0.055555556 | J16: =C16+I16 -> 1.0555556 | K16: =H16*0.5 -> 0.055555556
A19: PARTS BY NAR 6:4 Profit Sharing (5 - 10 STEPS)
A20: Photo | B20: Parts | C20: Naked Cost (RM) | D20: Qty | E20: EA Target Cost (USD) | F20: Price to Quote EA (USD) | G20: Price to Quote EA (RM) | H20: Profit | I20: NAR | K20: LADDERTECH | L20: Remarks
I21: 60% Profit Sharing (RM) | J21: Cost to Insert In PO/pc (RM) | K21: 40% Profit Sharing (RM)
A22: 1) Other Materials
B23: Griptread Nosing50mm | C23: 25 | D23: 1 | G23: =C23*1.1 -> 27.5 | H23: =G23-C23 -> 2.5 | I23: =H23*0.6 -> 1.5 | J23: =C23+I23 -> 26.5 | K23: =H23*0.4 -> 1
A24: 2) CNC & Welding (Based on Laser)
B25: Overall ladder | C25: 100 | D25: 1 | G25: =C25*1.1 -> 110 | H25: =G25-C25 -> 10 | I25: =H25*0.6 -> 6 | J25: =C25+I25 -> 106 | K25: =H25*0.4 -> 4
B26: Steps | C26: 30 | D26: 1 | G26: =C26*1.1 -> 33 | H26: =G26-C26 -> 3 | I26: =H26*0.6 -> 1.8 | J26: =C26+I26 -> 31.8 | K26: =H26*0.4 -> 1.2
A27: 3) Packaging Material by NAR
B28: Cardboard & Strecth Film | C28: 5 | D28: 1 | G28: =C28*1.1 -> 5.5 | H28: =G28-C28 -> 0.5 | I28: =H28*0.7 -> 0.35 | J28: =C28+I28 -> 5.35 | K28: =H28*0.4 -> 0.2
A29: 4) Bolt & Nut
B30: M10x20T | C30: 0.4 | D30: 1 | E30: 0.31 | F30: 0.3 | G30: =F30*4.3 -> 1.29 | H30: =G30-C30 -> 0.89 | I30: 0.3 | J30: 0.3 | K30: 0.59 | L30: Laddertech open mould and direct give RM0.30 to NAR
B31: M10NUT | C31: 0.14 | D31: 1 | F31: 0.25 | G31: =F31*4.3 -> 1.075 | H31: =G31-C31 -> 0.935 | I31: =H31*0.6 -> 0.561 | J31: =C31+I31 -> 0.701 | K31: =H31*0.4 -> 0.374 | L31: Own markup for Price quoted to EA. No %
B32: Rivet | C32: 1 | D32: 1 | G32: =C32/0.9 -> 1.1111111 | H32: =G32-C32 -> 0.11111111 | I32: =H32*0.6 -> 0.066666667 | J32: =C32+I32 -> 1.0666667 | K32: =H32*0.4 -> 0.044444444
A34: PARTS BY LADDERTECH
A35: Photo | B35: Parts | C35: Naked Cost (RM) | D35: Qty | E35: Price to Quote EA (RM)
A37: 6) Packaging Material by LADDERTECH (Estimation based on WHDP + 20% Markup) | F37: *We did not have any information on the packaging SOP yet
B38: Fragile tape (4 rolls/ ladder) | C38: =(2.2+(2.2*0.2))*4 -> 10.56 | D38: 1 | E38: =C38 -> 10.56
B39: Carton box | C39: =2.5+(2.5*0.2) -> 3 | D39: 1 | E39: 0
A40: Subtotal | E40: =SUM(E38:E39) -> 10.56
A41: 7) Marketing Materials by LADDERTECH (Estimation based on WHDP + 15% Markup) | F41: *We did not have complete information on the marketing materials
B42: Booklet & Zipper Bag | C42: =(0.75+(0.75*0.15))+(0.15+(0.15*0.15)) -> 1.035 | D42: 1 | E42: =C42 -> 1.035
B43: PVC Card | C43: =(4.4+(4.4*0.15)) -> 5.06 | D43: 1 | E43: =C43 -> 5.06
B44: Sticker Set | C44: =((0.23+0.84+10.56)+((0.23+0.84+10.56)*0.15)) -> 13.3745 | D44: 1 | E44: =C44 -> 13.3745
B45: Q/A Sticker | C45: =(1.15+(1.15*0.15)) -> 1.3225 | D45: 1 | E45: =C45 -> 1.3225
...

Sheet TO QUOTE EA (NAR PARTS)
A1: TO QUOTE EA (PARTS BY NAR)
A3: XLMP-0.9 - Ladder - 3 Steps (XLMP0.9LDR)
A4: Parts | B4: Price to Quote EA/pc (RM) | C4: Qty | D4: Total Price to Quote EA (RM) | E4: Remarks
A5: 1) Aluminium Extrusion (AA6061-T6)
A6: One Ladder | B6: =EXTRUSION!M16 -> 445.7756 | C6: 1 | D6: =B6*C6 -> 445.7756 | E6: AA6061-T6 = RM25.00/kg Refer Extrusion Costing Sheet | F6: RM22/KG
A7: Subtotal | D7: =D6 -> 445.7756 | F7: =EXTRUSION!N16 -> 392.28253
A8: 2) Other Materials
A9: Griptread Nosing50mm | B9: ='ACCESSORIES & OTHER PARTS'!G7 -> 27.5 | C9: 1 | D9: =B9*C9 -> 27.5
A10: Subtotal | D10: =SUM(D9:D9) -> 27.5 | F10: =D10 -> 27.5
A11: 3) CNC & Welding (Based on Laser)
A12: Overall ladder | B12: ='ACCESSORIES & OTHER PARTS'!G9 -> 110 | C12: 1 | D12: =B12*C12 -> 110 | F12: =(D12*(1-10%))*C12 -> 99
A13: Steps | B13: ='ACCESSORIES & OTHER PARTS'!G10 -> 33 | C13: 3 | D13: =B13*C13 -> 99 | F13: =(B13*(1-10%))*C13 -> 89.1
A14: Subtotal | D14: =SUM(D12:D13) -> 209 | F14: =SUM(F12:F13) -> 188.1
A15: 4) Packaging Material by NAR
A16: Cardboard & Strecth Film | B16: 5.5 | C16: 1 | D16: =B16*C16 -> 5.5
A17: Subtotal | D17: =SUM(D16:D16) -> 5.5 | F17: =D17 -> 5.5
A18: 5) Bolt & Nut
A19: M10x20T | B19: ='ACCESSORIES & OTHER PARTS'!G14 -> 1.29 | C19: 12 | D19: =B19*C19 -> 15.48
A20: M10NUT | B20: ='ACCESSORIES & OTHER PARTS'!G15 -> 1.075 | C20: 12 | D20: =B20*C20 -> 12.9
A21: Rivet | B21: ='ACCESSORIES & OTHER PARTS'!G16 -> 1.1111111 | C21: 3 | D21: =B21*C21 -> 3.3333333
A22: Subtotal | D22: =SUM(D19:D21) -> 31.713333 | F22: =D22 -> 31.713333
A23: Total Price | D23: =D7+D10+D14+D17+D22 -> 719.48893 | F23: =F7+F10+F14+F17+F22 -> 645.09586
A26: XLMP-1.2 - Ladder - 4 Steps (XLMP1.2LDR)
A27: Parts | B27: Price to Quote EA/pc (RM) | C27: Qty | D27: Total Price to Quote EA (RM) | E27: Remarks
A28: 1) Aluminium Extrusion (AA6061-T6)
A29: One Ladder | B29: =EXTRUSION!M34 -> 494.56999 | C29: 1 | D29: =B29*C29 -> 494.56999 | E29: AA6061-T6 = RM25.00/kg Refer Extrusion Costing Sheet | F29: RM22/KG
A30: Subtotal | D30: =D29 -> 494.56999 | F30: =EXTRUSION!N34 -> 435.22159
A31: 2) Other Materials
A32: Griptread Nosing50mm | B32: ='ACCESSORIES & OTHER PARTS'!G7 -> 27.5 | C32: 1 | D32: =B32*C32 -> 27.5
A33: Subtotal | D33: =SUM(D32:D32) -> 27.5 | F33: =D33 -> 27.5
A34: 3) CNC & Welding (Based on Laser)
A35: Overall ladder | B35: ='ACCESSORIES & OTHER PARTS'!G9 -> 110 | C35: 1 | D35: =B35*C35 -> 110 | F35: =(D35*(1-10%))*C35 -> 99
A36: Steps | B36: ='ACCESSORIES & OTHER PARTS'!G10 -> 33 | C36: 4 | D36: =B36*C36 -> 132 | F36: =(B36*(1-10%))*C36 -> 118.8
A37: Subtotal | D37: =SUM(D35:D36) -> 242 | F37: =SUM(F35:F36) -> 217.8
A38: 4) Packaging Material by NAR
A39: Cardboard & Strecth Film | B39: ='ACCESSORIES & OTHER PARTS'!G12 -> 5.5 | C39: 1 | D39: =B39*C39 -> 5.5
A40: Subtotal | D40: =SUM(D39:D39) -> 5.5 | F40: =D40 -> 5.5
A41: 5) Bolt & Nut
A42: M10x20T | B42: ='ACCESSORIES & OTHER PARTS'!G14 -> 1.29 | C42: 12 | D42: =B42*C42 -> 15.48
A43: M10NUT | B43: ='ACCESSORIES & OTHER PARTS'!G15 -> 1.075 | C43: 12 | D43: =B43*C43 -> 12.9
...

Sheet TO QUOTE EA
A1: TO QUOTE EA (NAR PARTS) - Currency USD3.80
A3: XLMP-0.9 - Ladder - 3 Steps (XLMP0.9LDR)
A4: Parts | B4: Total to Quote (RM) RM25/kg USD3.80 | C4: Total to Quote (RM) RM22/kg USD3.80 Welding (-5%) | D4: Total to Quote (RM) RM22/kg USD3.80 Welding (-5%) | E4: Remarks
A6: Aluminium Extrusion (AA6061-T6) | B6: ='TO QUOTE EA (NAR PARTS)'!D7 -> 445.7756 | C6: ='TO QUOTE EA (NAR PARTS)'!F7 -> 392.28253 | D6: =EXTRUSION!O17*3.9 -> 392.28253
A7: Other Materials (Est. from SBS Fiberglass Nosing) | B7: ='TO QUOTE EA (NAR PARTS)'!D10 -> 27.5 | C7: =B7 -> 27.5 | D7: =C7 -> 27.5
A8: CNC & Welding (Est. from STO vertical laser welding) | B8: ='TO QUOTE EA (NAR PARTS)'!D14 -> 209 | C8: ='TO QUOTE EA (NAR PARTS)'!F14 -> 188.1 | D8: =C8 -> 188.1
A9: Packaging Material by NAR | B9: ='TO QUOTE EA (NAR PARTS)'!D17 -> 5.5 | C9: =B9 -> 5.5 | D9: =C9 -> 5.5
A10: Bolt & Nut | B10: ='TO QUOTE EA (NAR PARTS)'!D22 -> 31.713333 | C10: =B10 -> 31.713333 | D10: =C10 -> 31.713333
A11: Packaging Material by LADDERTECH | B11: ='ACCESSORIES & OTHER PARTS'!E40 -> 10.56 | C11: =B11 -> 10.56 | D11: =C11 -> 10.56
A12: Marketing Materials by LADDERTECH | B12: ='ACCESSORIES & OTHER PARTS'!E46 -> 20.792 | C12: =B12 -> 20.792 | D12: =C12 -> 20.792
A13: FOB | B13: ='ACCESSORIES & OTHER PARTS'!E49 -> 35 | C13: =B13 -> 35 | D13: =C13 -> 35
A14: To Quote/ Unit (RM) | B14: =SUM(B6:B13) -> 785.84093 | C14: =SUM(C6:C13) -> 711.44786 | D14: =SUM(D6:D13) -> 711.44786
A15: To Quote (USD)/ Unit | B15: =B14/3.8 -> 206.80025 | C15: =C14/3.8 -> 187.22312 | D15: =D14/3.8 -> 187.22312 | E15: Currency USD3.80
A16: Final To Quote (USD)/ Unit | B16: 207 | C16: 188 | D16: 188
A19: XLMP-1.2- Ladder - 4 Steps (XLMP1.2LDR)
A20: Parts | B20: Total to Quote (RM) RM25/kg USD3.80 | C20: Total to Quote (RM) RM22/kg USD3.80 Welding (-5%) | D20: Total to Quote (RM) RM22/kg USD3.80 Welding (-5%) | E20: Remarks
A22: Aluminium Extrusion (AA6061-T6) | B22: ='TO QUOTE EA (NAR PARTS)'!D30 -> 494.56999 | C22: ='TO QUOTE EA (NAR PARTS)'!F30 -> 435.22159 | D22: ='TO QUOTE EA (NAR PARTS)'!G30 -> 0
A23: Other Materials (Est. from SBS Fiberglass Nosing) | B23: =$B$7 -> 27.5 | C23: =B23 -> 27.5 | D23: =C23 -> 27.5
A24: CNC & Welding (Est. from STO vertical laser welding) | B24: ='TO QUOTE EA (NAR PARTS)'!D37 -> 242 | C24: ='TO QUOTE EA (NAR PARTS)'!F37 -> 217.8 | D24: ='TO QUOTE EA (NAR PARTS)'!G37 -> 0
A25: Packaging Material by NAR | B25: =$B$9 -> 5.5 | C25: =B25 -> 5.5 | D25: =C25 -> 5.5
A26: Bolt & Nut | B26: =$B$10 -> 31.713333 | C26: =B26 -> 31.713333 | D26: =C26 -> 31.713333
A27: Packaging Material by LADDERTECH | B27: =$B$11 -> 10.56 | C27: =B27 -> 10.56 | D27: =C27 -> 10.56
A28: Marketing Materials by LADDERTECH | B28: =$B$12 -> 20.792 | C28: =B28 -> 20.792 | D28: =C28 -> 20.792
A29: FOB | B29: =$B$13 -> 35 | C29: =B29 -> 35 | D29: =C29 -> 35
A30: To Quote/ Unit (RM) | B30: =SUM(B22:B29) -> 867.63532 | C30: =SUM(C22:C29) -> 784.08692 | D30: =SUM(D22:D29) -> 131.06533
A31: To Quote (USD)/ Unit | B31: =B30/3.8 -> 228.32508 | C31: =C30/3.8 -> 206.33866 | D31: =D30/3.8 -> 34.490877 | E31: Currency USD3.80
A32: Final To Quote (USD)/ Unit | B32: 229 | C32: 207 | D32: 213
A35: XLMP-1.5- Ladder - 5 Steps (XLMP1.5LDR)
A36: Parts | B36: Total to Quote (RM) RM25/kg USD3.80 | C36: Total to Quote (RM) RM22/kg USD3.80 Welding (-5%) | D36: Total to Quote (RM) RM22/kg USD3.80 Welding (-5%) | E36: Remarks
A38: Aluminium Extrusion (AA6061-T6) | B38: ='TO QUOTE EA (NAR PARTS)'!D53 -> 543.36438 | C38: ='TO QUOTE EA (NAR PARTS)'!F53 -> 478.16065 | D38: ='TO QUOTE EA (NAR PARTS)'!G53 -> 0
A39: Other Materials (Est. from SBS Fiberglass Nosing) | B39: =$B$7 -> 27.5 | C39: =B39 -> 27.5 | D39: =C39 -> 27.5
A40: CNC & Welding (Est. from STO vertical laser welding) | B40: ='TO QUOTE EA (NAR PARTS)'!D60 -> 275 | C40: ='TO QUOTE EA (NAR PARTS)'!F60 -> 247.5 | D40: ='TO QUOTE EA (NAR PARTS)'!G60 -> 0
A41: Packaging Material by NAR | B41: =$B$9 -> 5.5 | C41: =B41 -> 5.5 | D41: =C41 -> 5.5
A42: Bolt & Nut | B42: =$B$10 -> 31.713333 | C42: =B42 -> 31.713333 | D42: =C42 -> 31.713333
A43: Packaging Material by LADDERTECH | B43: =$B$11 -> 10.56 | C43: =B43 -> 10.56 | D43: =C43 -> 10.56
A44: Marketing Materials by LADDERTECH | B44: =$B$12 -> 20.792 | C44: =B44 -> 20.792 | D44: =C44 -> 20.792
A45: FOB | B45: =$B$13 -> 35 | C45: =B45 -> 35 | D45: =C45 -> 35
A46: To Quote/ Unit (RM) | B46: =SUM(B38:B45) -> 949.42971 | C46: =SUM(C38:C45) -> 856.72598 | D46: =SUM(D38:D45) -> 131.06533
A47: To Quote (USD)/ Unit | B47: =B46/3.8 -> 249.84992 | C47: =C46/3.8 -> 225.45421 | D47: =D46/3.8 -> 34.490877 | E47: Currency USD3.80
A48: Final To Quote (USD)/ Unit | B48: 250 | C48: 226 | D48: 226
...

Sheet SUMMARY
B2: XLMP LADDER (BREAKDOWN)
B3: RM25/kg, USD3.80, FIBERGLASS NOSING BASED ON SBS, MIG WELDING BASED ON STEPOVER VERTICAL LASER COST
B4: PRODUCT MODEL | C4: TARGET PRICE/UNIT | D4: FINAL TO QUOTE/ UNIT | E4: BASED ON FINAL TO QUOTE
E5: EXTRUSION | I5: FIBERGLASS NOSING BOLT & NUT | J5: % | K5: CNC & MIG WELDING (EST FROM STO VERTICAL COST) | L5: % | M5: PACKAGING & MARKETING MATERIAL | N5: % | O5: FOB | P5: % | X5: LADDER PHOTOS
E6: LADDER | F6: % | G6: CAGE | H6: % | X6: 0.9 - 2.1
B7: XLMP0.9LDR | C7: 180 | D7: ='TO QUOTE EA'!B16 -> 207 | E7: =EXTRUSION!M17 -> 117.30937 | F7: =E7/D7 -> 0.56671193 | G7: 0 | H7: =G7/D7 -> 0 | I7: =('TO QUOTE EA'!B7+'TO QUOTE EA'!B10)/3.8 -> 15.582456 | J7: =I7/D7 -> 0.075277566 | K7: ='TO QUOTE EA'!B8/3.8 -> 55 | L7: =K7/D7 -> 0.26570048 | M7: =('TO QUOTE EA'!B105+'TO QUOTE EA'!B107+'TO QUOTE EA'!B108)/3.8 -> 9.6978947 | N7: =M7/D7 -> 0.046849733 | O7: ='TO QUOTE EA'!B109/3.8 -> 9.2105263 | P7: =O7/D7 -> 0.044495296 | Q7: =F7+H7+J7+L7+N7+P7 -> 0.999035
B8: XLMP1.2LDR | C8: 190 | D8: ='TO QUOTE EA'!B32 -> 229 | E8: =EXTRUSION!M35 -> 130.15 | F8: =E8/D8 -> 0.5683406 | G8: 0 | H8: =G8/D8 -> 0 | I8: =$I$7 -> 15.582456 | J8: =I8/D8 -> 0.06804566 | K8: ='TO QUOTE EA'!B24/3.8 -> 63.684211 | L8: =K8/D8 -> 0.27809699 | M8: =$M$7 -> 9.6978947 | N8: =M8/D8 -> 0.042348885 | O8: =$O$7 -> 9.2105263 | P8: =O8/D8 -> 0.040220639 | Q8: =F8+H8+J8+L8+N8+P8 -> 0.99705277
B9: XLMP1.5LDR | C9: 200 | D9: ='TO QUOTE EA'!B48 -> 250 | E9: =EXTRUSION!M52 -> 142.99063 | F9: =E9/D9 -> 0.5719625 | G9: 0 | H9: =G9/D9 -> 0 | I9: =$I$7 -> 15.582456 | J9: =I9/D9 -> 0.062329825 | K9: ='TO QUOTE EA'!B40/3.8 -> 72.368421 | L9: =K9/D9 -> 0.28947368 | M9: =$M$7 -> 9.6978947 | N9: =M9/D9 -> 0.038791579 | O9: =$O$7 -> 9.2105263 | P9: =O9/D9 -> 0.036842105 | Q9: =F9+H9+J9+L9+N9+P9 -> 0.99939969
B10: XLMP1.8LDR | C10: 220 | D10: ='TO QUOTE EA'!B64 -> 272 | E10: =EXTRUSION!M69 -> 155.83125 | F10: =E10/D10 -> 0.57290902 | G10: 0 | H10: =G10/D10 -> 0 | I10: =$I$7 -> 15.582456 | J10: =I10/D10 -> 0.057288442 | K10: ='TO QUOTE EA'!B56/3.8 -> 81.052632 | L10: =K10/D10 -> 0.29798762 | M10: =$M$7 -> 9.6978947 | N10: =M10/D10 -> 0.035654025 | O10: =$O$7 -> 9.2105263 | P10: =O10/D10 -> 0.033862229 | Q10: =F10+H10+J10+L10+N10+P10 -> 0.99770133
B11: XLMP2.1LDR | C11: 300 | D11: ='TO QUOTE EA'!B80 -> 293 | E11: =EXTRUSION!M86 -> 168.67188 | F11: =E11/D11 -> 0.57567195 | G11: 0 | H11: =G11/D11 -> 0 | I11: =$I$7 -> 15.582456 | J11: =I11/D11 -> 0.053182444 | K11: ='TO QUOTE EA'!B72/3.8 -> 89.736842 | L11: =K11/D11 -> 0.30626909 | M11: =$M$7 -> 9.6978947 | N11: =M11/D11 -> 0.033098617 | O11: =$O$7 -> 9.2105263 | P11: =O11/D11 -> 0.031435243 | Q11: =F11+H11+J11+L11+N11+P11 -> 0.99965734
B12: XLMP2.4LDR | C12: 350 | D12: ='TO QUOTE EA'!B96 -> 469 | E12: =((EXTRUSION!Q93*25)/0.9)/3.8 -> 181.51251 | F12: =E12/D12 -> 0.38702028 | G12: =((EXTRUSION!Q94*25)/0.9)/3.8 -> 141.65613 | H12: =G12/D12 -> 0.30203866 | I12: =('TO QUOTE EA'!B87+'TO QUOTE EA'!B90)/3.8 -> 30.519298 | J12: =I12/D12 -> 0.065073131 | K12: ='TO QUOTE EA'!B88/3.8 -> 98.421053 | L12: =K12/D12 -> 0.20985299 | M12: =$M$7 -> 9.6978947 | N12: =M12/D12 -> 0.020677814 | O12: =$O$7 -> 9.2105263 | P12: =O12/D12 -> 0.019638649 | Q12: =F12+H12+J12+L12+N12+P12 -> 1.0043015
B13: XLMP2.7LDR | C13: 400 | D13: ='TO QUOTE EA'!B112 -> 515 | E13: =((EXTRUSION!Q112*25)/0.9)/3.8 -> 194.35314 | F13: =E13/D13 -> 0.37738473 | G13: =((EXTRUSION!Q113*25)/0.9)/3.8 -> 163.76682 | H13: =G13/D13 -> 0.31799383 | I13: =$I$12 -> 30.519298 | J13: =I13/D13 -> 0.059260773 | K13: ='TO QUOTE EA'!B104/3.8 -> 107.10526 | L13: =K13/D13 -> 0.20797138 | M13: =$M$7 -> 9.6978947 | N13: =M13/D13 -> 0.018830864 | O13: =$O$7 -> 9.2105263 | P13: =O13/D13 -> 0.017884517 | Q13: =F13+H13+J13+L13+N13+P13 -> 0.9993261
B14: XLMP3.0LDR | C14: 450 | D14: ='TO QUOTE EA'!B128 -> 579 | E14: =((EXTRUSION!Q131*25)/0.9)/3.8 -> 207.19377 | F14: =E14/D14 -> 0.35784761 | G14: =((EXTRUSION!Q132*25)/0.9)/3.8 -> 199.03353 | H14: =G14/D14 -> 0.34375393 | I14: =('TO QUOTE EA'!B119+'TO QUOTE EA'!B122)/3.8 -> 37.987719 | J14: =I14/D14 -> 0.065609187 | K14: ='TO QUOTE EA'!B120/3.8 -> 115.78947 | L14: =K14/D14 -> 0.19998182 | M14: =$M$7 -> 9.6978947 | N14: =M14/D14 -> 0.016749386 | O14: =$O$7 -> 9.2105263 | P14: =O14/D14 -> 0.015907645 | Q14: =F14+H14+J14+L14+N14+P14 -> 0.99984958
B17: XLMP LADDER (BREAKDOWN)
B18: RM22/kg, USD3.80, FIBERGLASS NOSING BASED ON SBS, MIG WELDING BASED ON STEPOVER VERTICAL LASER COST (-5%)
B19: PRODUCT MODEL | C19: TARGET PRICE/UNIT | D19: FINAL TO QUOTE/ UNIT | E19: BASED ON FINAL TO QUOTE
E20: EXTRUSION | I20: FIBERGLASS NOSING BOLT & NUT | J20: % | K20: CNC & MIG WELDING (-5%) | L20: % | M20: PACKAGING & MARKETING MATERIAL | N20: % | O20: FOB | P20: % | X20: 2.4 - 2.7
E21: LADDER | F21: % | G21: CAGE | H21: %
B22: XLMP0.9LDR | C22: 180 | D22: ='TO QUOTE EA'!C16 -> 188 | E22: =EXTRUSION!N17 -> 103.23224 | F22: =E22/D22 -> 0.54910768 | G22: 0 | H22: =G22/D22 -> 0 | I22: =$I7 -> 15.582456 | J22: =I22/D22 -> 0.082885405 | K22: ='TO QUOTE EA (NAR PARTS)'!F14/3.8 -> 49.5 | L22: =K22/D22 -> 0.26329787 | M22: =$M$7 -> 9.6978947 | N22: =M22/D22 -> 0.051584546 | O22: =$O$7 -> 9.2105263 | P22: =O22/D22 -> 0.048992161 | Q22: =F22+H22+J22+L22+N22+P22 -> 0.99586767
B23: XLMP1.2LDR | C23: 190 | D23: ='TO QUOTE EA'!C32 -> 207 | E23: =EXTRUSION!N35 -> 114.532 | F23: =E23/D23 -> 0.55329467 | G23: 0 | H23: =G23/D23 -> 0 | I23: =$I8 -> 15.582456 | J23: =I23/D23 -> 0.075277566 | K23: ='TO QUOTE EA (NAR PARTS)'!F37/3.8 -> 57.315789 | L23: =K23/D23 -> 0.27688787 | M23: =$M$7 -> 9.6978947 | N23: =M23/D23 -> 0.046849733 | O23: =$O$7 -> 9.2105263 | P23: =O23/D23 -> 0.044495296 | Q23: =F23+H23+J23+L23+N23+P23 -> 0.99680514
B24: XLMP1.5LDR | C24: 200 | D24: ='TO QUOTE EA'!C48 -> 226 | E24: =EXTRUSION!N52 -> 125.83175 | F24: =E24/D24 -> 0.55677766 | G24: 0 | H24: =G24/D24 -> 0 | I24: =$I9 -> 15.582456 | J24: =I24/D24 -> 0.068948921 | K24: ='TO QUOTE EA (NAR PARTS)'!F60/3.8 -> 65.131579 | L24: =K24/D24 -> 0.28819283 | M24: =$M$7 -> 9.6978947 | N24: =M24/D24 -> 0.042911039 | O24: =$O$7 -> 9.2105263 | P24: =O24/D24 -> 0.040754541 | Q24: =F24+H24+J24+L24+N24+P24 -> 0.99758498
B25: XLMP1.8LDR | C25: 220 | D25: ='TO QUOTE EA'!C64 -> 245 | E25: =EXTRUSION!N69 -> 137.1315 | F25: =E25/D25 -> 0.55972042 | G25: 0 | H25: =G25/D25 -> 0 | I25: =$I10 -> 15.582456 | J25: =I25/D25 -> 0.063601862 | K25: ='TO QUOTE EA (NAR PARTS)'!F83/3.8 -> 72.947368 | L25: =K25/D25 -> 0.29774436 | M25: =$M$7 -> 9.6978947 | N25: =M25/D25 -> 0.039583244 | O25: =$O$7 -> 9.2105263 | P25: =O25/D25 -> 0.037593985 | Q25: =F25+H25+J25+L25+N25+P25 -> 0.99824387
B26: XLMP2.1LDR | C26: 300 | D26: ='TO QUOTE EA'!C80 -> 264 | E26: =EXTRUSION!N86 -> 148.43126 | F26: =E26/D26 -> 0.56223961 | G26: 0 | H26: =G26/D26 -> 0 | I26: =$I11 -> 15.582456 | J26: =I26/D26 -> 0.059024455 | K26: ='TO QUOTE EA (NAR PARTS)'!F106/3.8 -> 80.763158 | L26: =K26/D26 -> 0.30592105 | M26: =$M$7 -> 9.6978947 | N26: =M26/D26 -> 0.03673445 | O26: =$O$7 -> 9.2105263 | P26: =O26/D26 -> 0.034888357 | Q26: =F26+H26+J26+L26+N26+P26 -> 0.99880792
B27: XLMP2.4LDR | C27: 350 | D27: ='TO QUOTE EA'!C96 -> 420 | E27: =((EXTRUSION!Q93*22)/0.9)/3.8 -> 159.73101 | F27: =E27/D27 -> 0.38031193 | G27: =((EXTRUSION!Q94*22)/0.9)/3.8 -> 124.6574 | H27: =G27/D27 -> 0.29680332 | I27: =$I12 -> 30.519298 | J27: =I27/D27 -> 0.072664996 | K27: ='TO QUOTE EA (NAR PARTS)'!F129/3.8 -> 88.578947 | L27: =K27/D27 -> 0.21090226 | M27: =$M$7 -> 9.6978947 | N27: =M27/D27 -> 0.023090226 | O27: =$O$7 -> 9.2105263 | P27: =O27/D27 -> 0.021929825 | Q27: =F27+H27+J27+L27+N27+P27 -> 1.0057025
B28: XLMP2.7LDR | C28: 400 | D28: ='TO QUOTE EA'!C112 -> 461 | E28: =((EXTRUSION!Q112*22)/0.9)/3.8 -> 171.03076 | F28: =E28/D28 -> 0.37099948 | G28: =((EXTRUSION!Q113*22)/0.9)/3.8 -> 144.1148 | H28: =G28/D28 -> 0.31261345 | I28: =$I13 -> 30.519298 | J28: =I28/D28 -> 0.066202382 | K28: ='TO QUOTE EA (NAR PARTS)'!F152/3.8 -> 96.394737 | L28: =K28/D28 -> 0.20909921 | M28: =$M$7 -> 9.6978947 | N28: =M28/D28 -> 0.021036648 | O28: =$O$7 -> 9.2105263 | P28: =O28/D28 -> 0.01997945 | Q28: =F28+H28+J28+L28+N28+P28 -> 0.99993063
B29: XLMP3.0LDR | C29: 450 | D29: ='TO QUOTE EA'!C128 -> 519 | E29: =((EXTRUSION!Q131*22)/0.9)/3.8 -> 182.33051 | F29: =E29/D29 -> 0.3513112 | G29: =((EXTRUSION!Q132*22)/0.9)/3.8 -> 175.1495 | H29: =G29/D29 -> 0.33747496 | I29: =$I14 -> 37.987719 | J29: =I29/D29 -> 0.073194064 | K29: ='TO QUOTE EA (NAR PARTS)'!F175/3.8 -> 104.21053 | L29: =K29/D29 -> 0.20079099 | M29: =$M$7 -> 9.6978947 | N29: =M29/D29 -> 0.018685732 | O29: =$O$7 -> 9.2105263 | P29: =O29/D29 -> 0.017746679 | Q29: =F29+H29+J29+L29+N29+P29 -> 0.99920363
B32: XLMP LADDER (BREAKDOWN)
B33: RM22/kg, USD3.90, FIBERGLASS NOSING BASED ON SBS, MIG WELDING BASED ON STEPOVER VERTICAL LASER COST (-5%)
B34: PRODUCT MODEL | C34: TARGET PRICE/UNIT | D34: FINAL TO QUOTE/ UNIT | E34: BASED ON FINAL TO QUOTE | M34: FINAL PRICE/KG WHOLE LADDER | S34: FINAL PRICE/KG WHOLE LADDER | T34: FINAL PRICE/KG EXCLUDE PACKAGING, STICKER, & FOB | V34: FINAL PRICE/ UNIT FIBERGLASS NOSING BOLT & NUT | W34: FINAL PRICE/ UNIT PACKAGING, STICKER, & FOB | X34: FINAL TO QUOTE/ UNIT | Y34: 3
E35: EXTRUSION | I35: FIBERGLASS NOSING BOLT & NUT | J35: % | K35: CNC & MIG WELDING (-5%) | L35: % | N35: PACKAGING & MARKETING MATERIAL | O35: % | P35: FOB | Q35: % | U35: LADDER WEIGHT/ UNIT (KG)
E36: LADDER | F36: % | G36: CAGE | H36: %
A37: W/O CAGE | B37: XLMP0.9LDR | C37: 180 | D37: =E37+G37+I37+K37+N37+P37 -> 183.30691 | E37: =EXTRUSION!O17 -> 100.58526 | F37: =E37/D37 -> 0.54872598 | G37: 0 | H37: =G37/D37 -> 0 | I37: =$I22 -> 15.582456 | J37: =I37/D37 -> 0.085007467 | K37: ='TO QUOTE EA (NAR PARTS)'!F14/3.9 -> 48.230769 | L37: =L22-5% -> 0.21329787 | M37: =(D37*4)/EXTRUSION!K12 -> 47.102971 | N37: =$M$7 -> 9.6978947 | O37: =N37/D37 -> 0.052905233 | P37: =$O$7 -> 9.2105263 | Q37: =P37/D37 -> 0.050246476 | R37: =F37+H37+J37+L37+O37+Q37 -> 0.95018303 | S37: =(D37*4)/EXTRUSION!K12 -> 47.102971 | T37: =((E37+G37+K37)*3.9)/EXTRUSION!K12 -> 37.284112 | U37: =EXTRUSION!K15 -> 16.047922 | V37: =I37*3.9 -> 60.771579 | W37: =((N37+P37)*3.9) -> 73.742842 | X37: =((T37*U37)+W37+V37)/3.9 -> 187.90947
B38: XLMP1.2LDR | C38: 190 | D38: =E38+G38+I38+K38+N38+P38 -> 201.93231 | E38: =EXTRUSION!O35 -> 111.59528 | F38: =E38/D38 -> 0.55263707 | G38: 0 | H38: =G38/D38 -> 0 | I38: =$I23 -> 15.582456 | J38: =I38/D38 -> 0.07716673 | K38: ='TO QUOTE EA (NAR PARTS)'!F37/3.9 -> 55.846154 | L38: =L23-5% -> 0.22688787 | M38: =(D38*4)/EXTRUSION!K30 -> 46.769617 | N38: =$M$7 -> 9.6978947 | O38: =N38/D38 -> 0.048025473 | P38: =$O$7 -> 9.2105263 | Q38: =P38/D38 -> 0.045611949 | R38: =F38+H38+J38+L38+O38+Q38 -> 0.95032909 | S38: =(D38*4)/EXTRUSION!K30 -> 46.769617 | T38: =((E38+G38+K38)*3.9)/EXTRUSION!K30 -> 37.811643 | U38: =EXTRUSION!K33 -> 17.80452 | V38: =I38*3.9 -> 60.771579 | W38: =((N38+P38)*3.9) -> 73.742842 | X38: =((T38*U38)+W38+V38)/3.9 -> 207.11091
B39: XLMP1.5LDR | C39: 200 | D39: =E39+G39+I39+K39+N39+P39 -> 220.55771 | E39: =EXTRUSION!O52 -> 122.6053 | F39: =E39/D39 -> 0.55588759 | G39: 0 | H39: =G39/D39 -> 0 | I39: =$I24 -> 15.582456 | J39: =I39/D39 -> 0.070650244 | K39: ='TO QUOTE EA (NAR PARTS)'!F60/3.9 -> 63.461538 | L39: =L24-5% -> 0.23819283 | M39: =(D39*4)/EXTRUSION!K47 -> 46.496134 | N39: =$M$7 -> 9.6978947 | O39: =N39/D39 -> 0.043969874 | P39: =$O$7 -> 9.2105263 | Q39: =P39/D39 -> 0.041760165 | R39: =F39+H39+J39+L39+O39+Q39 -> 0.9504607 | S39: =(D39*4)/EXTRUSION!K47 -> 46.496134 | T39: =((E39+G39+K39)*3.9)/EXTRUSION!K47 -> 38.244429 | U39: =EXTRUSION!K50 -> 19.561118 | V39: =I39*3.9 -> 60.771579 | W39: =((N39+P39)*3.9) -> 73.742842 | X39: =((T39*U39)+W39+V39)/3.9 -> 226.31236
B40: XLMP1.8LDR | C40: 220 | D40: =E40+G40+I40+K40+N40+P40 -> 239.18311 | E40: =EXTRUSION!O69 -> 133.61531 | F40: =E40/D40 -> 0.55863188 | G40: 0 | H40: =G40/D40 -> 0 | I40: =$I25 -> 15.582456 | J40: =I40/D40 -> 0.065148647 | K40: ='TO QUOTE EA (NAR PARTS)'!F83/3.9 -> 71.076923 | L40: =L25-5% -> 0.24774436 | M40: =(D40*4)/EXTRUSION!K64 -> 46.267721 | N40: =$M$7 -> 9.6978947 | O40: =N40/D40 -> 0.040545901 | P40: =$O$7 -> 9.2105263 | Q40: =P40/D40 -> 0.038508264 | R40: =F40+H40+J40+L40+O40+Q40 -> 0.95057905 | S40: =(D40*4)/EXTRUSION!K64 -> 46.267721 | T40: =((E40+G40+K40)*3.9)/EXTRUSION!K64 -> 38.605891 | U40: =EXTRUSION!K67 -> 21.317715 | V40: =I40*3.9 -> 60.771579 | W40: =((N40+P40)*3.9) -> 73.742842 | X40: =((T40*U40)+W40+V40)/3.9 -> 245.5138
B41: XLMP2.1LDR | C41: 300 | D41: =E41+G41+I41+K41+N41+P41 -> 257.80851 | E41: =(EXTRUSION!O86) -> 144.62533 | F41: =E41/D41 -> 0.56097964 | G41: 0 | H41: =G41/D41 -> 0 | I41: =$I26 -> 15.582456 | J41: =I41/D41 -> 0.060441977 | K41: ='TO QUOTE EA (NAR PARTS)'!F106/3.9 -> 78.692308 | L41: =L26-5% -> 0.25592105 | M41: =(D41*4)/EXTRUSION!K81 -> 46.074085 | N41: =$M$7 -> 9.6978947 | O41: =N41/D41 -> 0.037616659 | P41: =$O$7 -> 9.2105263 | Q41: =P41/D41 -> 0.035726231 | R41: =F41+H41+J41+L41+O41+Q41 -> 0.95068556 | S41: =(D41*4)/EXTRUSION!K81 -> 46.074085 | T41: =((E41+G41+K41)*3.9)/EXTRUSION!K81 -> 38.912318 | U41: =EXTRUSION!K84 -> 23.074313 | V41: =I41*3.9 -> 60.771579 | W41: =((N41+P41)*3.9) -> 73.742842 | X41: =((T41*U41)+W41+V41)/3.9 -> 264.71524
A42: W/ CAGE | B42: XLMP2.4LDR | C42: 350 | D42: =E42+G42+I42+K42+N42+P42 -> 412.83181 | E42: =((EXTRUSION!Q93*22)/0.9)/3.9 -> 155.63534 | F42: =E42/D42 -> 0.37699455 | G42: =((EXTRUSION!Q94*22)/0.9)/3.9 -> 121.46105 | H42: =G42/D42 -> 0.29421438 | I42: =$I27 -> 30.519298 | J42: =I42/D42 -> 0.073926713 | K42: ='TO QUOTE EA (NAR PARTS)'!F129/3.9 -> 86.307692 | L42: =L27-5% -> 0.16090226 | M42: =(D42*4)/EXTRUSION!K17 -> #DIV/0! | N42: =$M$7 -> 9.6978947 | O42: =N42/D42 -> 0.023491152 | P42: =$O$7 -> 9.2105263 | Q42: =P42/D42 -> 0.022310603 | R42: =F42+H42+J42+L42+O42+Q42 -> 0.95183965 | S42: =(D42*4)/EXTRUSION!K100 -> 38.507568 | T42: =((N42+P42)*4)/EXTRUSION!K17 -> #DIV/0! | W42: =((N42+P42)*4) -> 75.633684 | X42: =((T42*U42)+W42)/3.9 -> #DIV/0!
B43: XLMP2.7LDR | C43: 400 | D43: =E43+G43+I43+K43+N43+P43 -> 450.4157 | E43: =((EXTRUSION!Q112*22)/0.9)/3.9 -> 166.64536 | F43: =E43/D43 -> 0.36998123 | G43: =((EXTRUSION!Q113*22)/0.9)/3.9 -> 140.41955 | H43: =G43/D43 -> 0.31175545 | I43: =$I28 -> 30.519298 | J43: =I43/D43 -> 0.067758069 | K43: ='TO QUOTE EA (NAR PARTS)'!F152/3.9 -> 93.923077 | L43: =L28-5% -> 0.15909921 | M43: =(D43*4)/EXTRUSION!K18 -> #DIV/0! | N43: =$M$7 -> 9.6978947 | O43: =N43/D43 -> 0.021530987 | P43: =$O$7 -> 9.2105263 | Q43: =P43/D43 -> 0.020448946 | R43: =F43+H43+J43+L43+O43+Q43 -> 0.9505739 | S43: =(D43*4)/EXTRUSION!K119 -> 37.912913 | T43: =((N43+P43)*4)/EXTRUSION!K18 -> #DIV/0! | W43: =((N43+P43)*4) -> 75.633684 | X43: =((T43*U43)+W43)/3.9 -> #DIV/0!
B44: XLMP3.0LDR | C44: 450 | D44: =E44+G44+I44+K44+N44+P44 -> 511.42361 | E44: =((EXTRUSION!Q131*22)/0.9)/3.8 -> 182.33051 | F44: =E44/D44 -> 0.35651564 | G44: =((EXTRUSION!Q132*22)/0.9)/3.9 -> 170.65849 | H44: =G44/D44 -> 0.33369303 | I44: =$I29 -> 37.987719 | J44: =I44/D44 -> 0.074278384 | K44: ='TO QUOTE EA (NAR PARTS)'!F175/3.9 -> 101.53846 | L44: =L29-5% -> 0.15079099 | M44: =(D44*4)/EXTRUSION!K19 -> #DIV/0! | N44: =$M$7 -> 9.6978947 | O44: =N44/D44 -> 0.018962548 | P44: =$O$7 -> 9.2105263 | Q44: =P44/D44 -> 0.018009584 | R44: =F44+H44+J44+L44+O44+Q44 -> 0.95225018 | S44: =(D44*4)/EXTRUSION!K138 -> 37.950179 | T44: =((N44+P44)*4)/EXTRUSION!K19 -> #DIV/0! | W44: =((N44+P44)*4) -> 75.633684 | X44: =((T44*U44)+W44)/3.9 -> #DIV/0!
B47: XLMP LADDER (BREAKDOWN)
...

Sheet SUMMARY WITHOUT CAGE
B2: LADDER PHOTOS
B4: NO CAGE 3 - 7 STEPS
B5: XLMP0.9LDR - XLMP2.1LDR
B7: XLMP LADDER (BREAKDOWN)
B8: RM22/kg, USD3.90, FIBERGLASS NOSING BASED ON SBS, MIG WELDING BASED ON STEPOVER VERTICAL LASER COST (-5%)
B9: PRODUCT MODEL | C9: EA TARGET PRICE/ UNIT | D9: FINAL TO QUOTE/ UNIT | E9: FINAL PRICE/KG WHOLE LADDER | F9: FINAL TO QUOTE/ UNIT | G9: FINAL PRICE/KG EXCLUDE FIBERGLASS NOSING, BOLT & NUT, PACKAGING, STICKER & FOB | H9: LADDER WEIGHT/ UNIT (KG) | I9: PRICE/ UNIT PACKAGING, STICKER & FOB | J9: PRICE/ UNIT FIBERGLASS NOSING BOLT & NUT | L9: OUR FINAL TO QUOTE DIFF FROM TARGET PRICE | M9: (-15%)
B11: MODEL WITH NO CAGE
B12: XLMP0.9LDR | C12: 180 | D12: =((H12*G12)+I12+J12)/3.9 -> 187.90947 | E12: =(D12*3.9)/H12 -> 45.666158 | F12: 190 | G12: =SUMMARY!T37 -> 37.284112 | H12: =SUMMARY!U37 -> 16.047922 | I12: =SUMMARY!W37 -> 73.742842 | J12: =SUMMARY!V37 -> 60.771579 | L12: =F12-C12 -> 10 | M12: =F12*(1-15%) -> 161.5
B13: XLMP1.2LDR | C13: 190 | D13: =((H13*G13)+I13+J13)/3.9 -> 207.11091 | E13: =(D13*3.9)/H13 -> 45.366714 | F13: 210 | G13: =SUMMARY!T38 -> 37.811643 | H13: =SUMMARY!U38 -> 17.80452 | I13: =SUMMARY!W38 -> 73.742842 | J13: =SUMMARY!V38 -> 60.771579 | L13: =F13-C13 -> 20 | M13: =F13*(1-15%) -> 178.5
B14: XLMP1.5LDR | C14: 200 | D14: =((H14*G14)+I14+J14)/3.9 -> 226.31236 | E14: =(D14*3.9)/H14 -> 45.121051 | F14: 230 | G14: =SUMMARY!T39 -> 38.244429 | H14: =SUMMARY!U39 -> 19.561118 | I14: =SUMMARY!W39 -> 73.742842 | J14: =SUMMARY!V39 -> 60.771579 | L14: =F14-C14 -> 30 | M14: =F14*(1-15%) -> 195.5
B15: XLMP1.8LDR | C15: 220 | D15: =((H15*G15)+I15+J15)/3.9 -> 245.5138 | E15: =(D15*3.9)/H15 -> 44.915874 | F15: 250 | G15: =SUMMARY!T40 -> 38.605891 | H15: =SUMMARY!U40 -> 21.317715 | I15: =SUMMARY!W40 -> 73.742842 | J15: =SUMMARY!V40 -> 60.771579 | L15: =F15-C15 -> 30 | M15: =F15*(1-15%) -> 212.5
B16: XLMP2.1LDR | C16: 300 | D16: =((H16*G16)+I16+J16)/3.9 -> 264.71524 | E16: =(D16*3.9)/H16 -> 44.741936 | F16: 270 | G16: =SUMMARY!T41 -> 38.912318 | H16: =SUMMARY!U41 -> 23.074313 | I16: =SUMMARY!W41 -> 73.742842 | J16: =SUMMARY!V41 -> 60.771579 | L16: EA saves USD30.00 | M16: =F16*(1-15%) -> 229.5
B17: MODEL WITH CAGE
B18: XLMP2.4LDR | C18: ='SUMMARY WITH CAGE'!C13 -> 350 | D18: ='SUMMARY WITH CAGE'!F13 -> 420.25322 | E18: =(D18*3.9)/H18 -> #DIV/0! | F18: ='SUMMARY WITH CAGE'!G13 -> 425 | G18: =F18-C18 -> 75
B19: XLMP2.7LDR | C19: ='SUMMARY WITH CAGE'!C14 -> 400 | D19: ='SUMMARY WITH CAGE'!F14 -> 457.83712 | E19: =(D19*3.9)/H19 -> #DIV/0! | F19: ='SUMMARY WITH CAGE'!G14 -> 460 | G19: =F19-C19 -> 60
B20: XLMP3.0LDR | C20: ='SUMMARY WITH CAGE'!C15 -> 450 | D20: ='SUMMARY WITH CAGE'!F15 -> 515.57449 | E20: =(D20*3.9)/H20 -> #DIV/0! | F20: ='SUMMARY WITH CAGE'!G15 -> 520 | G20: =F20-C20 -> 70
E22: =E13-E12 -> -0.2994436 | F22: =F13-F12 -> 20
E23: =E14-E13 -> -0.24566323 | F23: =F14-F13 -> 20
E24: =E15-E14 -> -0.20517751 | F24: =F15-F14 -> 20
E25: =E16-E15 -> -0.17393807 | F25: =F16-F15 -> 20
F26: =F18-F16 -> 155
F27: =F19-F18 -> 35
F28: =F20-F19 -> 60
F29: =F13-F12 -> 20 | G29: =F12-C12 -> 10
F30: =F14-F13 -> 20 | G30: =F13-C13 -> 20
F31: =F15-F14 -> 20 | G31: =F14-C14 -> 30
F32: =F16-F15 -> 20

Sheet SUMMARY WITH CAGE
B2: LADDER PHOTOS
B4: 2 CAGE RINGS 8 STEPS CAGE HEIGHT: 1565MM | C4: 2 CAGE RINGS 9 STEPS CAGE HEIGHT: 1865MM | D4: 3 CAGE RINGS 10 STEPS CAGE HEIGHT: 2165MM
B5: XLMP2.4LDR | C5: XLMP2.7LDR | D5: XLMP3.0LDR
B7: XLMP LADDER (BREAKDOWN)
B8: RM22/kg, USD3.90, FIBERGLASS NOSING BASED ON SBS, MIG WELDING BASED ON STEPOVER VERTICAL LASER COST (-5%)
B9: PRODUCT MODEL | C9: EA TARGET PRICE/ UNIT | D9: EA ESTIMATE TARGET PRICE/UNIT (REVERSE CALCULATION) | F9: FINAL TO QUOTE/ UNIT | G9: ROUNDED OFF FINAL TO QUOTE/ UNIT | H9: FINAL PRICE/KG EXCLUDE FIBERGLASS NOSING, BOLT & NUT, PACKAGING, STICKER & FOB | K9: WEIGHT/ UNIT (KG) | N9: PRICE/ UNIT PACKAGING, STICKER & FOB | O9: PRICE/ UNIT | Q9: BASED ON FINAL TO QUOTE
Q10: EXTRUSION | W10: FIBERGLASS NOSING & BOLT & NUT | AA10: CNC & MIG WELDING (-5%) | AE10: PACKAGING & MARKETING MATERIAL | AF10: % | AG10: FOB | AH10: %
C11: WHOLE SET | D11: LADDER | E11: CAGE | H11: LADDER RM22/KG | I11: CAGE VERTICAL BAR RM22/KG | J11: CAGE RING RM30/KG | K11: LADDER | L11: CAGE VERTICAL BAR | M11: CAGE RING | O11: LADDER FIBERGLASS NOSING BOLT & NUT | P11: CAGE BOLT & NUT | Q11: LADDER | R11: % | S11: CAGE VERTICAL BAR | T11: % | U11: CAGE RING | V11: % | W11: LADDER NOSING, BOLT & NUT | X11: % | Y11: CAGE BOLT & NUT | Z11: % | AA11: LADDER CNC & WELDING | AB11: % | AC11: CAGE NO WELDING CNC & BENDING | AD11: %
B12: MODEL WITH CAGE
B13: XLMP2.4LDR | C13: 350 | D13: =((H13*K13)+N13+O13)/3.9 -> 276.03436 | E13: =((I13*L13)+(J13*M13)+P13)/3.9 -> 144.21886 | F13: =D13+E13 -> 420.25322 | G13: 425 | H13: =((Q13+AA13)*3.9)/EXTRUSION!Q93 -> 38.000129 | I13: =(S13*3.9)/(EXTRUSION!K94/0.97) -> 24.444444 | J13: =(U13*3.9)/(EXTRUSION!K95/0.97) -> 33.333333 | K13: =EXTRUSION!Q93 -> 24.830911 | L13: =EXTRUSION!K94/0.97 -> 15.779072 | M13: =EXTRUSION!K95/0.97 -> 3.5994866 | N13: ='SUMMARY WITHOUT CAGE'!$I$12 -> 73.742842 | O13: =W13*3.9 -> 59.213333 | P13: =Y13*3.9 -> 56.76 | Q13: =((EXTRUSION!Q93*22)/0.9)/3.9 -> 155.63534 | R13: =Q13/F13 -> 0.37033706 | S13: =(((EXTRUSION!K94/0.97)*22)/0.9)/3.9 -> 98.900167 | T13: =S13/F13 -> 0.23533471 | U13: =(((EXTRUSION!K95/0.97)*30)/0.9)/3.9 -> 30.764843 | V13: =U13/F13 -> 0.07320549 | W13: ='TO QUOTE EA (NAR PARTS)'!I152 -> 15.182906 | X13: =W13/F13 -> 0.036127995 | Y13: ='TO QUOTE EA (NAR PARTS)'!L152 -> 14.553846 | Z13: =Y13/F13 -> 0.034631136 | AA13: =SUMMARY!K42 -> 86.307692 | AB13: =AA13/F13 -> 0.20537069 | AC13: 0 | AD13: =AC13/Z13 -> 0 | AE13: =SUMMARY!$N$42 -> 9.6978947 | AF13: =AE13/F13 -> 0.023076313 | AG13: =SUMMARY!$O$57 -> 9.2105263 | AH13: =AG13/F13 -> 0.021916611 | AI13: =R13+T13+V13+X13+Z13+AB13+AD13+AF13+AH13 -> 1
B14: XLMP2.7LDR | C14: 400 | D14: =((H14*K14)+N14+O14)/3.9 -> 294.65976 | E14: =((I14*L14)+(J14*M14)+P14)/3.9 -> 163.17735 | F14: =D14+E14 -> 457.83712 | G14: 460 | H14: =((Q14+AA14)*3.9)/EXTRUSION!Q112 -> 38.221591 | I14: =(S14*3.9)/(EXTRUSION!K113/0.97) -> 24.444444 | J14: =(U14*3.9)/(EXTRUSION!K114/0.97) -> 33.333333 | K14: =EXTRUSION!Q112 -> 26.587509 | L14: =EXTRUSION!K113/0.97 -> 18.803814 | M14: =EXTRUSION!K114/0.97 -> 3.5994866 | N14: ='SUMMARY WITHOUT CAGE'!$I$12 -> 73.742842 | O14: =W14*3.9 -> 59.213333 | P14: =Y14*3.9 -> 56.76 | Q14: =((EXTRUSION!Q112*22)/0.9)/3.9 -> 166.64536 | R14: =Q14/F14 -> 0.36398394 | S14: =(((EXTRUSION!K113/0.97)*22)/0.9)/3.9 -> 117.85867 | T14: =S14/F14 -> 0.25742488 | U14: =(((EXTRUSION!K114/0.97)*30)/0.9)/3.9 -> 30.764843 | V14: =U14/F14 -> 0.067196043 | W14: =$W$13 -> 15.182906 | X14: =W14/F14 -> 0.033162244 | Y14: =Y13 -> 14.553846 | Z14: =Y14/F14 -> 0.031788262 | AA14: =SUMMARY!K43 -> 93.923077 | AB14: =AA14/F14 -> 0.20514518 | AC14: 0 | AD14: =AC14/Z14 -> 0 | AE14: =SUMMARY!$N$42 -> 9.6978947 | AF14: =AE14/F14 -> 0.021181976 | AG14: =SUMMARY!$O$57 -> 9.2105263 | AH14: =AG14/F14 -> 0.020117474 | AI14: =R14+T14+V14+X14+Z14+AB14+AD14+AF14+AH14 -> 1
B15: XLMP3.0LDR | C15: 450 | D15: =((H15*K15)+N15+O15)/3.9 -> 310.77929 | E15: =((I15*L15)+(J15*M15)+P15)/3.9 -> 204.7952 | F15: =D15+E15 -> 515.57449 | G15: 520 | H15: =((Q15+AA15)*3.9)/EXTRUSION!Q131 -> 38.070808 | I15: =(S15*3.9)/(EXTRUSION!K132/0.97) -> 24.444444 | J15: =(U15*3.9)/(EXTRUSION!K133/0.97) -> 33.333333 | K15: =EXTRUSION!Q131 -> 28.344107 | L15: =EXTRUSION!K132/0.97 -> 21.828557 | M15: =EXTRUSION!K133/0.97 -> 5.3992299 | N15: ='SUMMARY WITHOUT CAGE'!$I$12 -> 73.742842 | O15: =W15*3.9 -> 59.213333 | P15: =Y15*3.9 -> 85.14 | Q15: =((EXTRUSION!Q132*22)/0.9)/3.8 -> 175.1495 | R15: =Q15/F15 -> 0.33971717 | S15: =(((EXTRUSION!K132/0.97)*22)/0.9)/3.9 -> 136.81716 | T15: =S15/F15 -> 0.26536837 | U15: =(((EXTRUSION!K133/0.97)*30)/0.9)/3.9 -> 46.147264 | V15: =U15/F15 -> 0.089506492 | W15: =$W$13 -> 15.182906 | X15: =W15/F15 -> 0.029448521 | Y15: ='TO QUOTE EA (NAR PARTS)'!L175 -> 21.830769 | Z15: =Y15/F15 -> 0.042342609 | AA15: =SUMMARY!K44 -> 101.53846 | AB15: =AA15/F15 -> 0.19694237 | AC15: 0 | AD15: =AC15/Z15 -> 0 | AE15: =SUMMARY!$N$42 -> 9.6978947 | AF15: =AE15/F15 -> 0.018809881 | AG15: =SUMMARY!$O$57 -> 9.2105263 | AH15: =AG15/F15 -> 0.017864589 | AI15: =R15+T15+V15+X15+Z15+AB15+AD15+AF15+AH15 -> 1
G17: =G14-G13 -> 35 | H17: =G13-C13 -> 75
G18: =G15-G14 -> 60 | H18: =G14-C14 -> 60
H19: =G15-C15 -> 70
